* [逆引きRuby - 例外](http://www.namaraii.com/rubytips/?%CE%E3%B3%B0)
* [8. エラーと例外 - Python v2.6.2 documentation](http://www.python.jp/doc/release/tutorial/errors.html)


##例外を捕捉する

try-except で囲う。

[8. エラーと例外 — Python v2.6.2 documentation](http://www.python.jp/doc/release/tutorial/errors.html)


> try 文は下記のように動作します。

> * まず、 try 節 (try clause) (キーワード try と except の間の文) が実行されます。
> * 何も例外が発生しなければ、 except 節 をスキップして try 文の実行を終えます。
> * try 節内の実行中に例外が発生すると、その節の残りは飛ばされます。次に、例外型が except キーワードの後に指定されている例外に一致する場合、except 節が実行された後、 try 節の後の文に実行が継続されます。
> * もしも except 節で指定された例外と一致しない例外が発生すると、その例外は try 文の外側に渡されます。例外に対するハンドラ (handler、処理部) がどこにもなければ、 処理されない例外 (unhandled exception) となり、上記に示したようなメッセージを出して実行を停止します。

    >>> try:
    ...     f = open("not_exist")
    ... except:
    ...     print "ooooooops!!"
    ...
    ooooooops!!



##特定の例外だけを捕捉する

    >>> try:
    ...     f = open("not_exist")
    ... except IOError:
    ...     print "io error"
    ... except ValueError:
    ...     print "Could not convert data to an integer."
    ... except:
    ...     print "oooooooops!!"
    ...
    io error

##例外処理の後に処理をやり直す


##例外の内容を受け取る

    >>> try:
    ...     f = open("not_exist")
    ... except Exception as inst:
    ...     print type(inst)
    ...     print inst.args
    ...     print inst
    ...
    <type 'exceptions.IOError'>
    (2, 'No such file or directory')
    [Errno 2] No such file or directory: 'not_exist'

##例外を発生させる

    >>> try:
    ...     raise NameError, 'HiThere'
    ... except NameError:
    ...     print 'An exception flew by!'
    ...
    An exception flew by!

##独自の例外を定義し発生させる

    >>> class MyError(Exception):
    ...     def __init__(self, value):
    ...             self.value = value
    ...     def __str__(self):
    ...             return repr(self.value)
    ...
    >>> try:
    ...     raise MyError(2*2)
    ... except MyError as e:
    ...     print 'My exception occurred, value:', e.value
    ...
    My exception occurred, value: 4
    >>> raise MyError, 'oops!'
    Traceback (most recent call last):
      File "<stdin>", line 1, in <module>
    __main__.MyError: 'oops!'

##省略記法(def)


##省略記法(後置)
